Workbook

Sheet 총괄
B1: 고체연료 과제 연구비 편성
H2: 작성일 | I2: 46067 | J2: 수정일
B3: 연구비할당 | C3: 195000 | D3: 316000 | E3: 316000 | F3: 316000 | G3: 316000 | I3: =SUM(C3:H3) -> 1459000 | L3: 차년도 별 구성비
A4: 비 목 | C4: 1차년도 | D4: 2차년도 | E4: 3차년도 | F4: 4차년도 | G4: 5차년도 | I4: 합 계 | J4: 구성비 | L4: 1차년도 | M4: 2차년도 | N4: 3차년도 | O4: 4차년도 | P4: 5차년도
A5: 직접비 | C5: =SUM(C6:C11) -> 172414 | D5: =SUM(D6:D11) -> 279400 | E5: =SUM(E6:E11) -> 279400 | F5: =SUM(F6:F11) -> 279400 | G5: =SUM(G6:G11) -> 279400 | I5: =SUM(C5:H5) -> 1290014 | J5: =I5/$I$13 -> 0.88417683 | L5: =C5/C$13 -> 0.88417436 | M5: =D5/D$13 -> 0.88417722 | N5: =E5/E$13 -> 0.88417722 | O5: =F5/F$13 -> 0.88417722 | P5: =G5/G$13 -> 0.88417722
B6: 인건비 | C6: =인건비!E11 -> 56400 | D6: =인건비!G11 -> 125100 | E6: =인건비!I11 -> 93900 | F6: =인건비!K11 -> 66199 | G6: =인건비!M11 -> 125100 | I6: =SUM(C6:G6) -> 466699 | J6: =I6/$I$13 -> 0.31987594 | L6: =C6/C$13 -> 0.28923077 | M6: =D6/D$13 -> 0.39588608 | N6: =E6/E$13 -> 0.2971519 | O6: =F6/F$13 -> 0.20949051 | P6: =G6/G$13 -> 0.39588608
B7: 학생인건비 | C7: 0 | D7: 0 | E7: 0 | F7: 0 | G7: 0 | I7: =SUM(C7:H7) -> 0 | L7: =C7/C$13 -> 0 | M7: =D7/D$13 -> 0 | N7: =E7/E$13 -> 0 | O7: =F7/F$13 -> 0 | P7: =G7/G$13 -> 0
B8: 연구시설장비및재료비 | C8: =직접비!E8 -> 71534 | D8: =직접비!H8 -> 54780 | E8: =직접비!K8 -> 113320 | F8: =직접비!N8 -> 151562 | G8: =직접비!Q8 -> 55880 | I8: =SUM(C8:H8) -> 447076 | J8: =I8/$I$13 -> 0.30642632 | L8: =C8/C$13 -> 0.36684103 | M8: =D8/D$13 -> 0.17335443 | N8: =E8/E$13 -> 0.35860759 | O8: =F8/F$13 -> 0.47962658 | P8: =G8/G$13 -> 0.17683544
B9: 연구활동비 | C9: =직접비!E42 -> 18700 | D9: =직접비!H42 -> 43500 | E9: =직접비!K42 -> 28900 | F9: =직접비!N42 -> 23900 | G9: =직접비!Q42 -> 48900 | I9: =SUM(C9:H9) -> 163900 | J9: =I9/$I$13 -> 0.11233722 | L9: =C9/C$13 -> 0.095897436 | M9: =D9/D$13 -> 0.13765823 | N9: =E9/E$13 -> 0.091455696 | O9: =F9/F$13 -> 0.075632911 | P9: =G9/G$13 -> 0.15474684
B10: 연구과제추진비 | C10: =직접비!E54 -> 14500 | D10: =직접비!H54 -> 31000 | E10: =직접비!K54 -> 24500 | F10: =직접비!N54 -> 24500 | G10: =직접비!Q54 -> 24500 | I10: =SUM(C10:H10) -> 119000 | J10: =I10/$I$13 -> 0.081562714 | L10: =C10/C$13 -> 0.074358974 | M10: =D10/D$13 -> 0.098101266 | N10: =E10/E$13 -> 0.077531646 | O10: =F10/F$13 -> 0.077531646 | P10: =G10/G$13 -> 0.077531646
B11: 연구수당 | C11: =ROUNDDOWN((C6+C7)*0.2,0) -> 11280 | D11: =ROUNDDOWN((D6+D7)*0.2,0) -> 25020 | E11: =ROUNDDOWN((E6+E7)*0.2,0) -> 18780 | F11: =ROUNDDOWN((F6+F7)*0.2,0) -> 13239 | G11: =ROUNDDOWN((G6+G7)*0.2,0) -> 25020 | I11: =SUM(C11:H11) -> 93339 | J11: =I11/$I$13 -> 0.06397464 | L11: =C11/C$13 -> 0.057846154 | M11: =D11/D$13 -> 0.079177215 | N11: =E11/E$13 -> 0.05943038 | O11: =F11/F$13 -> 0.04189557 | P11: =G11/G$13 -> 0.079177215
A12: 간접비 | C12: =C18 -> 22586 | D12: =D18 -> 36600 | E12: =E18 -> 36600 | F12: =F18 -> 36600 | G12: =G18 -> 36600 | I12: =SUM(C12:H12) -> 168986 | J12: =I12/$I$13 -> 0.11582317 | L12: =C12/C$13 -> 0.11582564 | M12: =D12/D$13 -> 0.11582278 | N12: =E12/E$13 -> 0.11582278 | O12: =F12/F$13 -> 0.11582278 | P12: =G12/G$13 -> 0.11582278
B13: 계 | C13: =C5+C12 -> 195000 | D13: =D5+D12 -> 316000 | E13: =E5+E12 -> 316000 | F13: =F5+F12 -> 316000 | G13: =G5+G12 -> 316000 | H13: =H5+H12 -> 0 | I13: =SUM(C13:G13) -> 1459000 | J13: =I13/$I$13*100 -> 100 | L13: =C13/C$13 -> 1 | M13: =D13/D$13 -> 1 | N13: =E13/E$13 -> 1 | O13: =F13/F$13 -> 1 | P13: =G13/G$13 -> 1
C14: =C8+C9+C10 -> 104734 | D14: =D8+D9+D10 -> 129280 | E14: =E8+E9+E10 -> 166720 | F14: =F8+F9+F10 -> 199962 | G14: =G8+G9+G10 -> 129280 | H14: =H8+H9+H10 -> 0
B15: 추가금액 | C15: =C3-C13 -> 0 | D15: =D3-D13 -> 0 | E15: =E3-E13 -> 0 | F15: =F3-F13 -> 0 | G15: =G3-G13 -> 0 | H15: =H3-H13 -> 0
B17: 직접비 | C17: =ROUNDUP(C3/(1+$B$19),0) -> 172414 | D17: =ROUNDUP(D3/(1+$B$19),0) -> 279399 | E17: =ROUNDUP(E3/(1+$B$19),0) -> 279399 | F17: =ROUNDUP(F3/(1+$B$20),0) -> 279399 | G17: =ROUNDUP(G3/(1+$B$20),0) -> 279399 | H17: =ROUNDUP(H3/(1.1433),0) -> 0
B18: 간접비 | C18: =ROUNDDOWN(C17*$B$19,0) -> 22586 | D18: =ROUNDDOWN(D17*$B$19-1,0) -> 36600 | E18: =ROUNDDOWN(E17*$B$19-1,0) -> 36600 | F18: =ROUNDDOWN(F17*$B$20-1,0) -> 36600 | G18: =ROUNDDOWN(G17*$B$20-1,0) -> 36600 | H18: =ROUNDDOWN(H17*0.1433,0) -> 0 | I18: =SUM(C18:G18) -> 168986
B19: 0.131 | C19: =SUM(C17:C18) -> 195000 | D19: =SUM(D17:D18) -> 315999 | E19: =SUM(E17:E18) -> 315999 | F19: =SUM(F17:F18) -> 315999 | G19: =SUM(G17:G18) -> 315999 | H19: =SUM(H17:H18) -> 0
B20: 0.131
B21: 간접비 비율 | C21: =C12/C5 -> 0.13099864 | D21: =D12/D5 -> 0.13099499 | E21: =E12/E5 -> 0.13099499 | F21: =F12/F5 -> 0.13099499 | G21: =G12/G5 -> 0.13099499 | H21: =H12/H5 -> #DIV/0!
B22: 연구수당 비율 | C22: =C11/(C6+C7) -> 0.2 | D22: =D11/(D6+D7) -> 0.2 | E22: =E11/(E6+E7) -> 0.2 | F22: =F11/(F6+F7) -> 0.19998792 | G22: =G11/(G6+G7) -> 0.2 | H22: =H11/(H6+H7) -> #DIV/0!
A24: 1 | B24: 비목 | C24: 세목 | F24: 1단계 | I24: 2단계 | K24: 합계
A25: 2 | F25: 1차년도 | G25: 2차년도 | H25: 3차년도 | I25: 1차년도 | J25: 2차년도
A26: 3 | B26: 직접비 | C26: 인건비 | D26: 내부인건비(A) | E26: 현금(N) | F26: =C6 -> 56400 | G26: =D6 -> 125100 | H26: =E6 -> 93900 | I26: =F6 -> 66199 | J26: =G6 -> 125100 | K26: =SUM(F26:J26) -> 466699
A27: 4 | E27: 현물 | F27: 0 | G27: 0 | H27: 0 | I27: 0 | J27: 0 | K27: =SUM(F27:J27) -> 0
A28: 5 | D28: 외부인건비(B) | E28: 현금(O) | K28: =SUM(F28:J28) -> 0
A29: 7 | D29: 연구지원인력인건비(C) | K29: =SUM(F29:J29) -> 0
A30: 8 | D30: 소계(A+B+C) | F30: =F26 -> 56400 | G30: =G26 -> 125100 | H30: =H26 -> 93900 | I30: =I26 -> 66199 | J30: =J26 -> 125100 | K30: =SUM(F30:J30) -> 466699
A31: 9 | C31: 학생 인건비(D) | E31: 일반 | F31: 0 | G31: 0 | H31: 0 | I31: 0 | J31: 0 | K31: =SUM(F31:J31) -> 0
A32: 10 | E32: 통합관리 | F32: 0 | G32: 0 | H32: 0 | I32: 0 | J32: 0 | K32: =SUM(F32:J32) -> 0
A33: 11 | C33: 총 인건비(E1=A+B+C+D) | F33: =F26+F28+F29+F31 -> 56400 | G33: =G26+G28+G29+G31 -> 125100 | H33: =H26+H28+H29+H31 -> 93900 | I33: =I26+I28+I29+I31 -> 66199 | J33: =J26+J28+J29+J31 -> 125100 | K33: =SUM(F33:J33) -> 466699
A34: 12 | C34: 수정인건비(E2=A+B+D) | F34: =F26+F28+F31 -> 56400 | G34: =G26+G28+G31 -> 125100 | H34: =H26+H28+H31 -> 93900 | I34: =I26+I28+I31 -> 66199 | J34: =J26+J28+J31 -> 125100 | K34: =SUM(F34:J34) -> 466699
A35: 13 | C35: 연구시설‧장비비(F) | E35: 현금(P) | F35: 0 | G35: 0 | H35: 0 | I35: 0 | J35: 0 | K35: =SUM(F35:J35) -> 0
A36: 14 | E36: 현물 | F36: 0 | G36: 0 | H36: 0 | I36: 0 | J36: 0 | K36: =SUM(F36:J36) -> 0
A37: 15 | C37: (연구시설‧장비비 중 통합관리비(현금)) | F37: 0 | G37: 0 | H37: 0 | I37: 0 | J37: 0 | K37: =SUM(F37:J37) -> 0
A38: 16 | C38: 연구재료비(G) | E38: 현금(Q) | F38: =C8 -> 71534 | G38: =D8 -> 54780 | H38: =E8 -> 113320 | I38: =F8 -> 151562 | J38: =G8 -> 55880 | K38: =SUM(F38:J38) -> 447076
A39: 17 | E39: 현물 | F39: 0 | G39: 0 | H39: 0 | I39: 0 | J39: 0 | K39: =SUM(F39:J39) -> 0
A40: 18 | C40: 연구활동비(H) | E40: 현금(R) | F40: =C9+C10 -> 33200 | G40: =D9+D10 -> 74500 | H40: =E9+E10 -> 53400 | I40: =F9+F10 -> 48400 | J40: =G9+G10 -> 73400 | K40: =SUM(F40:J40) -> 282900
A41: 19 | E41: 현물 | F41: 0 | G41: 0 | H41: 0 | I41: 0 | J41: 0 | K41: =SUM(F41:J41) -> 0
A42: 20 | C42: 연구수당(I) | F42: =C11 -> 11280 | G42: =D11 -> 25020 | H42: =E11 -> 18780 | I42: =F11 -> 13239 | J42: =G11 -> 25020 | K42: =SUM(F42:J42) -> 93339
...

Sheet 인건비
A1: 내부인건비 | D1: 1차년도 | F1: 2차년도 | H1: 3차년도 | J1: 4차년도 | L1: 5차년도 | N1: 총계 | O1: 총
D2: 개월 | E2: 9 | F2: 개월 | G2: 12 | H2: 개월 | I2: 12 | J2: 개월 | K2: 12 | L2: 개월 | M2: 12 | O2: =E2+G2+I2+K2+M2 -> 57 | P2: 개월
A3: 이름 | B3: 연봉 | C3: 월급여 | D3: 참여율 | E3: 지급액 | F3: 참여율 | G3: 지급액 | H3: 참여율 | I3: 지급액 | J3: 참여율 | K3: 지급액 | L3: 참여율 | M3: 지급액 | O3: 평균참여율
A4: 박창대 | B4: 130000 | C4: =ROUND(B4/12,0) -> 10833 | D4: 0.13 | E4: =ROUND($C4*D4*E$2,0) -> 12675 | F4: 0.2 | G4: =ROUND($C4*F4*G$2,0) -> 25999 | H4: 0.18 | I4: =ROUND($C4*H4*I$2,0) -> 23399 | J4: 0.13 | K4: =ROUND($C4*J4*K$2,0) -> 16899 | L4: 0.2 | M4: =ROUND($C4*L4*M$2,0) -> 25999 | N4: =E4+G4+I4+K4+M4 -> 104971 | O4: =N4/(C4*$O$2) -> 0.16999875
A5: 임병주 | B5: 120000 | C5: =ROUND(B5/12,0) -> 10000 | D5: 0.11 | E5: =ROUND($C5*D5*E$2,0) -> 9900 | F5: 0.17 | G5: =ROUND($C5*F5*G$2,0) -> 20400 | H5: 0.15 | I5: =ROUND($C5*H5*I$2,0) -> 18000 | J5: 0.11 | K5: =ROUND($C5*J5*K$2,0) -> 13200 | L5: 0.17 | M5: =ROUND($C5*L5*M$2,0) -> 20400 | N5: =E5+G5+I5+K5+M5 -> 81900 | O5: =N5/(C5*$O$2) -> 0.14368421
A6: 조성훈 | B6: 110000 | C6: =ROUND(B6/12,0) -> 9167 | D6: 0.11 | E6: =ROUND($C6*D6*E$2,0) -> 9075 | F6: 0.17 | G6: =ROUND($C6*F6*G$2,0) -> 18701 | H6: 0.15 | I6: =ROUND($C6*H6*I$2,0) -> 16501 | J6: 0.11 | K6: =ROUND($C6*J6*K$2,0) -> 12100 | L6: 0.17 | M6: =ROUND($C6*L6*M$2,0) -> 18701 | N6: =E6+G6+I6+K6+M6 -> 75078 | O6: =N6/(C6*$O$2) -> 0.14368473
A7: 권시은 | B7: 30000 | C7: =ROUND(B7/12,0) -> 2500 | D7: 0.3 | E7: =ROUND($C7*D7*E$2,0) -> 6750 | F7: 0.5 | G7: =ROUND($C7*F7*G$2,0) -> 15000 | H7: 0.3 | I7: =ROUND($C7*H7*I$2,0) -> 9000 | J7: 0.2 | K7: =ROUND($C7*J7*K$2,0) -> 6000 | L7: 0.5 | M7: =ROUND($C7*L7*M$2,0) -> 15000 | N7: =E7+G7+I7+K7+M7 -> 51750 | O7: =N7/(C7*$O$2) -> 0.36315789
A8: 이가람 | B8: 60000 | C8: =ROUND(B8/12,0) -> 5000 | D8: 0.3 | E8: =ROUND($C8*D8*E$2,0) -> 13500 | F8: 0.5 | G8: =ROUND($C8*F8*G$2,0) -> 30000 | H8: 0.3 | I8: =ROUND($C8*H8*I$2,0) -> 18000 | J8: 0.2 | K8: =ROUND($C8*J8*K$2,0) -> 12000 | L8: 0.5 | M8: =ROUND($C8*L8*M$2,0) -> 30000 | N8: =E8+G8+I8+K8+M8 -> 103500 | O8: =N8/(C8*$O$2) -> 0.36315789
A9: 파룩 | B9: 30000 | C9: =ROUND(B9/12,0) -> 2500 | D9: 0.2 | E9: =ROUND($C9*D9*E$2,0) -> 4500 | F9: 0.5 | G9: =ROUND($C9*F9*G$2,0) -> 15000 | H9: 0.3 | I9: =ROUND($C9*H9*I$2,0) -> 9000 | J9: 0.2 | K9: =ROUND($C9*J9*K$2,0) -> 6000 | L9: 0.5 | M9: =ROUND($C9*L9*M$2,0) -> 15000 | N9: =E9+G9+I9+K9+M9 -> 49500 | O9: =N9/(C9*$O$2) -> 0.34736842
D10: 0 | E10: =ROUND($C10*D10*E$2,0) -> 0 | F10: 0 | G10: =ROUND($C10*F10*G$2,0) -> 0 | H10: 0 | I10: =ROUND($C10*H10*I$2,0) -> 0 | J10: 0 | K10: =ROUND($C10*J10*K$2,0) -> 0 | L10: 0 | M10: =ROUND($C10*L10*M$2,0) -> 0 | N10: =E10+G10+I10+K10+M10 -> 0 | O10: =N10/(C10*$O$2) -> #DIV/0!
A11: 소계 | E11: =SUM(E4:E10) -> 56400 | G11: =SUM(G4:G10) -> 125100 | I11: =SUM(I4:I10) -> 93900 | K11: =SUM(K4:K10) -> 66199 | M11: =SUM(M4:M10) -> 125100 | N11: =E11+G11+I11+K11+M11 -> 466699
A13: 총 | B13: =COUNTA(A4:A10) -> 6 | C13: 명 | D13: 에너지 | E13: =E4+E5+E6+E7+E8+E9 -> 56400 | G13: =G4+G5+G6+G7+G8+G9 -> 125100 | I13: =I4+I5+I6+I7+I8+I9 -> 93900 | K13: =K4+K5+K6+K7+K8+K9 -> 66199 | M13: =M4+M5+M6+M7+M8+M9 -> 125100 | N13: =N4+N5+N6+N7+N8+N9 -> 466699
A14: 여성 | B14: 2 | C14: 명 | D14: 신뢰성 | E14: =#REF!+#REF! -> #REF! | G14: =#REF!+#REF! -> #REF! | I14: =#REF!+#REF! -> #REF! | K14: =#REF!+#REF! -> #REF! | M14: =#REF!+#REF! -> #REF! | N14: =#REF!+#REF! -> #REF!
B15: =B14/B13 -> 0.33333333

Sheet 직접비
A1: 비목 | B1: 품명 | C1: 1차년도 | F1: 2차년도 | I1: 3차년도 | L1: 4차년도 | O1: 5차년도 | R1: 6차년도
C2: 수량 | D2: 단가 | E2: 금액 | F2: 수량 | G2: 단가 | H2: 금액 | I2: 수량 | J2: 단가 | K2: 금액 | L2: 수량 | M2: 단가 | N2: 금액 | O2: 수량 | P2: 단가 | Q2: 금액 | R2: 수량 | S2: 단가 | T2: 금액
A3: 재료비 | D3: 소계 | E3: =E4+E6+E8+E37+E39 -> 71534 | G3: 소계 | H3: =H4+H6+H8+H37+H39 -> 54780 | J3: 소계 | K3: =K4+K6+K8+K37+K39 -> 113320 | M3: 소계 | N3: =N4+N6+N8+N37+N39 -> 151562 | P3: 소계 | Q3: =Q4+Q6+Q8+Q37+Q39 -> 55880 | S3: 소계 | T3: =T4+T6+T8+T34+T36 -> 0
A4: 1) 연구기자재 | D4: 소계 | E4: =SUM(E5:E5) -> 0 | G4: 소계 | H4: =SUM(H5:H5) -> 0 | J4: 소계 | K4: =SUM(K5:K5) -> 0 | M4: 소계 | N4: =SUM(N5:N5) -> 0 | P4: 소계 | Q4: =SUM(Q5:Q5) -> 0 | S4: 소계 | T4: =SUM(T5:T5) -> 0
C5: 0 | D5: 0 | E5: =C5*D5 -> 0 | F5: 0 | G5: 0 | H5: =F5*G5 -> 0 | I5: 0 | J5: 0 | K5: =I5*J5 -> 0 | L5: 0 | M5: 0 | N5: =L5*M5 -> 0 | O5: 0 | P5: 0 | Q5: =O5*P5 -> 0 | R5: 0 | S5: 0 | T5: =R5*S5 -> 0
A6: 2) 시설비 | D6: 소계 | E6: =SUM(E7:E7) -> 0 | G6: 소계 | H6: =SUM(H7:H7) -> 0 | J6: 소계 | K6: =SUM(K7:K7) -> 0 | M6: 소계 | N6: =SUM(N7:N7) -> 0 | P6: 소계 | Q6: =SUM(Q7:Q7) -> 0 | S6: 소계 | T6: =SUM(T7:T7) -> 0
C7: 0 | D7: 0 | E7: =C7*D7 -> 0 | F7: 0 | G7: 0 | H7: =F7*G7 -> 0 | I7: 0 | J7: 0 | K7: =I7*J7 -> 0 | L7: 0 | M7: 0 | N7: =L7*M7 -> 0 | O7: 0 | P7: 0 | Q7: =O7*P7 -> 0 | R7: 0 | S7: 0 | T7: =R7*S7 -> 0
A8: 3) 시약 및 재료비 | D8: 소계 | E8: =SUM(E10:E36) -> 71534 | G8: 소계 | H8: =ROUNDDOWN(SUM(H10:H36),0) -> 54780 | J8: 소계 | K8: =ROUNDDOWN(SUM(K10:K36),0) -> 113320 | M8: 소계 | N8: =ROUNDDOWN(SUM(N10:N36),0) -> 151562 | P8: 소계 | Q8: =ROUNDDOWN(SUM(Q10:Q36),0) -> 55880 | S8: 소계 | T8: =ROUNDDOWN(SUM(T10:T32),0) -> 0
A10: 1차년도 | B10: 에너지자립형 담수화 시스템 실험 장치 제작 | C10: 1 | D10: 40000 | E10: =C10*D10 -> 40000 | F10: 0 | G10: 0 | H10: =F10*G10 -> 0 | J10: 0 | K10: =I10*J10 -> 0 | M10: 0 | N10: =L10*M10 -> 0 | P10: 0 | Q10: =O10*P10 -> 0
B11: 분석용 PC, 노트북(수치해석용, 공정분석용) | C11: 2 | D11: 10000 | E11: =C11*D11 -> 20000 | F11: 0 | G11: 0 | H11: =F11*G11 -> 0 | J11: 0 | K11: =I11*J11 -> 0 | M11: 0 | N11: =L11*M11 -> 0 | P11: 0 | Q11: =O11*P11 -> 0
B12: 계측 센서, 실험용 DAQ (NI PXI DAQ) | C12: 1 | D12: 8000 | E12: =C12*D12 -> 8000 | F12: 0 | G12: 0 | H12: =F12*G12 -> 0 | J12: 0 | K12: =I12*J12 -> 0 | M12: 0 | N12: =L12*M12 -> 0 | P12: 0 | Q12: =O12*P12 -> 0
A13: 2차년도 | B13: 에너지 공급 시스템 제작 또는 구매 | D13: 0 | E13: =C13*D13 -> 0 | F13: 2 | G13: 15000 | H13: =F13*G13 -> 30000 | J13: 0 | K13: =I13*J13 -> 0 | M13: 0 | N13: =L13*M13 -> 0 | P13: 0 | Q13: =O13*P13 -> 0
B14: 분석용 PC, 노트북(수치해석용, 공정분석용) | D14: 0 | E14: =C14*D14 -> 0 | F14: 1 | G14: 10000 | H14: =F14*G14 -> 10000 | J14: 0 | K14: =I14*J14 -> 0 | M14: 0 | N14: =L14*M14 -> 0 | P14: 0 | Q14: =O14*P14 -> 0
B15: 계측 센서, 실험용 DAQ (NI PXI DAQ) | F15: 1 | G15: 8000 | H15: =F15*G15 -> 8000 | Q15: 0
E16: ` | F16: 0 | G16: 0 | H16: =F16*G16 -> 0 | Q16: 0
D17: 0 | E17: =C17*D17 -> 0 | F17: 0 | H17: =F17*G17 -> 0 | J17: 0 | K17: =I17*J17 -> 0 | M17: 0 | N17: =L17*M17 -> 0 | P17: 0 | Q17: =O17*P17 -> 0
A18: 3차년도 | B18: 히트펌프 제작 또는 구매 | D18: 0 | E18: =C18*D18 -> 0 | G18: 0 | H18: =F18*G18 -> 0 | I18: 1 | J18: 50000 | K18: =I18*J18 -> 50000 | M18: 0 | N18: =L18*M18 -> 0 | P18: 0 | Q18: 0
B19: 연속형 담수화 시스템 실험 장치 제작 | F19: 0 | G19: 0 | H19: =F19*G19 -> 0 | I19: 1 | J19: 50000 | K19: =I19*J19 -> 50000 | Q19: 0
B20: 계측 센서, 실험용 DAQ (NI PXI DAQ) | F20: 0 | G20: 0 | H20: =F20*G20 -> 0 | I20: 1 | J20: 8000 | K20: =I20*J20 -> 8000 | Q20: 0
D21: 0 | E21: =C21*D21 -> 0 | F21: 0 | G21: 0 | H21: =F21*G21 -> 0 | I21: 0 | J21: 0 | K21: =I21*J21 -> 0 | M21: 0 | N21: =L21*M21 -> 0 | P21: 0 | Q21: 0
D22: 0 | E22: =C22*D22 -> 0 | G22: 0 | H22: =F22*G22 -> 0 | J22: 0 | K22: =I22*J22 -> 0 | M22: 0 | N22: =L22*M22 -> 0 | P22: 0 | Q22: 0
A23: 4차년도 | B23: 이동형 통합 담수화 시스템 시작품 제작 | D23: 0 | E23: =C23*D23 -> 0 | G23: 0 | H23: =F23*G23 -> 0 | J23: 0 | K23: =I23*J23 -> 0 | L23: 1 | M23: 100000 | N23: =L23*M23 -> 100000 | Q23: 0
B24: 모니터링 시스템 구축 | F24: 0 | G24: 0 | H24: =F24*G24 -> 0 | L24: 1 | M24: 30000 | N24: =L24*M24 -> 30000 | Q24: 0 | V24: 신뢰성
B25: 분석용 PC, 노트북(수치해석용, 공정분석용) | D25: 0 | E25: =C25*D25 -> 0 | G25: 0 | H25: =F25*G25 -> 0 | J25: 0 | K25: =I25*J25 -> 0 | L25: 1 | M25: 10000 | N25: =L25*M25 -> 10000 | P25: 0 | Q25: 0 | U25: 현재 | V25: =E11+H15+K20+N25+#REF!+#REF!+#REF!+#REF!+#REF!+#REF!+#REF!+#REF! -> #REF!
B26: 계측 센서, 실험용 DAQ (NI PXI DAQ) | D26: 0 | E26: =C26*D26 -> 0 | G26: 0 | H26: =F26*G26 -> 0 | J26: 0 | K26: =I26*J26 -> 0 | L26: 1 | M26: 8000 | N26: =L26*M26 -> 8000 | P26: 0 | Q26: 0
A27: 5차년도 | B27: 이동형 통합 담수화 시스템 시작품 보완 | D27: 0 | E27: =C27*D27 -> 0 | H27: =F27*G27 -> 0 | K27: =I27*J27 -> 0 | N27: =L27*M27 -> 0 | O27: 1 | P27: 40000 | Q27: =O27*P27 -> 40000 | U27: 기존 | V27: 388000
B28: 계측 센서, 실험용 DAQ (NI PXI DAQ) | F28: 0 | G28: 0 | H28: =F28*G28 -> 0 | O28: 1 | P28: 8000 | Q28: =O28*P28 -> 8000
D29: 0 | E29: =C29*D29 -> 0 | F29: 0 | G29: 0 | H29: =F29*G29 -> 0 | K29: =I29*J29 -> 0 | N29: =L29*M29 -> 0 | O29: 0 | P29: 0 | Q29: 0
D30: 0 | E30: =C30*D30 -> 0 | H30: =F30*G30 -> 0 | K30: =I30*J30 -> 0 | N30: =L30*M30 -> 0 | Q30: 0
A31: 공통 | D31: 0 | E31: =C31*D31 -> 0 | H31: =F31*G31 -> 0 | K31: =I31*J31 -> 0 | N31: =L31*M31 -> 0 | P31: 0 | Q31: 0
E32: =C32*D32 -> 0 | F32: 0 | G32: 0 | H32: =F32*G32 -> 0 | K32: =I32*J32 -> 0 | M32: 0 | N32: =L32*M32 -> 0 | P32: 0 | Q32: =O32*P32 -> 0 | T32: =R32*S32 -> 0
N33: =L33*M33 -> 0 | P33: 0 | Q33: =O33*P33 -> 0
B34: 소모성 재료비 | C34: 1 | D34: 3534 | E34: =C34*D34 -> 3534 | F34: 1 | G34: 6780 | H34: =F34*G34 -> 6780 | I34: 1 | J34: 5320 | K34: =I34*J34 -> 5320 | L34: 1 | M34: 3562 | N34: =L34*M34 -> 3562 | O34: 1 | P34: 7880 | Q34: =O34*P34 -> 7880 | S34: 소계 | T34: =SUM(T35:T35) -> 0
E35: =C35*D35 -> 0 | H35: =F35*G35 -> 0 | K35: =I35*J35 -> 0 | N35: =L35*M35 -> 0 | Q35: =O35*P35 -> 0 | R35: 0 | S35: 0 | T35: =R35*S35 -> 0
E36: =C36*D36 -> 0 | H36: =F36*G36 -> 0 | K36: =I36*J36 -> 0 | N36: =L36*M36 -> 0 | P36: 0 | Q36: =O36*P36 -> 0 | S36: 소계 | T36: =SUM(T37:T38) -> 0
A37: 4)시험분석료 | D37: 소계 | E37: =SUM(E38:E38) -> 0 | G37: 소계 | H37: =SUM(H38:H38) -> 0 | J37: 소계 | K37: =SUM(K38:K38) -> 0 | M37: 소계 | N37: =SUM(N38:N38) -> 0 | P37: 소계 | Q37: =SUM(Q38:Q38) -> 0 | R37: 0 | S37: 0 | T37: =R37*S37 -> 0
C38: 0 | D38: 0 | E38: =C38*D38 -> 0 | F38: 0 | G38: 0 | H38: =F38*G38 -> 0 | I38: 0 | J38: 0 | K38: =I38*J38 -> 0 | L38: 0 | M38: 0 | N38: =L38*M38 -> 0 | O38: 0 | P38: 0 | Q38: =O38*P38 -> 0
A39: 5)시작품제작비 | D39: 소계 | E39: =SUM(E40:E41) -> 0 | G39: 소계 | H39: =SUM(H40:H41) -> 0 | J39: 소계 | K39: =SUM(K40:K41) -> 0 | M39: 소계 | N39: =SUM(N40:N41) -> 0 | P39: 소계 | Q39: =SUM(Q40:Q41) -> 0
C40: 0 | D40: 0 | E40: =C40*D40 -> 0 | F40: 0 | G40: 0 | H40: =F40*G40 -> 0 | I40: 0 | J40: 0 | K40: =I40*J40 -> 0 | L40: 0 | M40: 0 | N40: =L40*M40 -> 0 | O40: 0 | P40: 0 | Q40: =O40*P40 -> 0
A42: 연구활동비 | D42: 소계 | E42: =SUM(E43:E53) -> 18700 | G42: 소계 | H42: =SUM(H43:H53) -> 43500 | J42: 소계 | K42: =SUM(K43:K53) -> 28900 | M42: 소계 | N42: =SUM(N43:N53) -> 23900 | P42: 소계 | Q42: =SUM(Q43:Q53) -> 48900
...
